multiprocessing.pool.RemoteTraceback:
"""
Traceback (most recent call last):
  File "/usr/local/Cellar/python@3.10/3.10.6_1/Frameworks/Python.framework/Versions/3.10/lib/python3.10/multiprocessing/pool.py", line 125, in worker
    result = (True, func(*args, **kwds))
  File "/usr/local/Cellar/python@3.10/3.10.6_1/Frameworks/Python.framework/Versions/3.10/lib/python3.10/multiprocessing/pool.py", line 51, in starmapstar
    return list(itertools.starmap(args[0], args[1]))
  File "/Users/dsteinhoefel/PycharmProjects/InputConstraints/src/isla/performance_evaluator.py", line 762, in evaluate_kpaths
    covered_k_paths = {inp_id: compute_k_paths(inp) for _, (inp_id, inp) in input_bundle}
  File "/Users/dsteinhoefel/PycharmProjects/InputConstraints/src/isla/performance_evaluator.py", line 762, in <dictcomp>
    covered_k_paths = {inp_id: compute_k_paths(inp) for _, (inp_id, inp) in input_bundle}
  File "/Users/dsteinhoefel/PycharmProjects/InputConstraints/src/isla/performance_evaluator.py", line 745, in compute_k_paths
    return [path_to_string(path) for path in graph.k_paths_in_tree(inp, k, include_terminals=False)]
  File "/Users/dsteinhoefel/PycharmProjects/InputConstraints/venv/lib/python3.10/site-packages/grammar_graph/gg.py", line 542, in k_paths_in_tree
    all_paths = self.graph_paths_from_tree(tree, include_terminals=True)
  File "/Users/dsteinhoefel/PycharmProjects/InputConstraints/venv/lib/python3.10/site-packages/grammar_graph/gg.py", line 458, in graph_paths_from_tree
    traverse_tree(tree, action, kind=TRAVERSE_POSTORDER, reverse=True)
  File "/Users/dsteinhoefel/PycharmProjects/InputConstraints/venv/lib/python3.10/site-packages/grammar_graph/helpers.py", line 33, in traverse_tree
    if node[1]:
IndexError: string index out of range
"""

The above exception was the direct cause of the following exception:

Traceback (most recent call last):
  File "/Users/dsteinhoefel/PycharmProjects/InputConstraints/evaluations/evaluate_tar.py", line 132, in <module>
    evaluator.run()
  File "/Users/dsteinhoefel/PycharmProjects/InputConstraints/src/isla/performance_evaluator.py", line 226, in run
    self.compute_kpaths()
  File "/Users/dsteinhoefel/PycharmProjects/InputConstraints/src/isla/performance_evaluator.py", line 295, in compute_kpaths
    pool.starmap(evaluate_kpaths, args)
  File "/usr/local/Cellar/python@3.10/3.10.6_1/Frameworks/Python.framework/Versions/3.10/lib/python3.10/multiprocessing/pool.py", line 375, in starmap
    return self._map_async(func, iterable, starmapstar, chunksize).get()
  File "/usr/local/Cellar/python@3.10/3.10.6_1/Frameworks/Python.framework/Versions/3.10/lib/python3.10/multiprocessing/pool.py", line 774, in get
    raise self._value
IndexError: string index out of range
